Workbook

Sheet OPC
E1: OBSERVACION PREVENTIVA DE COMPORTAMIENTOS OPC | Y1: X
A2: CODIGO: JU-S-SSO-FOR-007 | N2: FECHA: 27/01/19 | S2: VERSION: 4
A3: Nombre de Observador: | F3: Edy Villasante | P3: Fecha: | R3: 43599
A4: Actividad/Tarea observada: | F4: Instalacion de Malla a tierra | P4: Empresa: | R4: CCICSK
A5: Area: | C5: Chancadora primaria de sulfuros | L5: Disciplina: | N5: Electricidad
A6: 1. GENERALES | U6: S | V6: R | W6: NA
A7: 1.1 | B7: Transita por accesos seguros en su área de trabajo. | U7: X | Y7: =IF(U7="X","S",IF(V7="X","R","NA")) -> S
A8: 1.2 | B8: Se ubica de manera que evita ser golpeada o entrar en contacto con algun equipo, herramienta o algo que pudiera causarle lesión en caso se suelte, caiga o resbale. | U8: X | Y8: =IF(U8="X","S",IF(V8="X","R","NA")) -> S
A9: 1.3 | B9: Mantiene postura adecuada al realizar su trabajo evitando causarse alguna lesión, lumbago , esguince. | U9: X | Y9: =IF(U9="X","S",IF(V9="X","R","NA")) -> S
A10: 1.4 | B10: Asegura que este distanciado a puntos de atrapamiento de su cuerpo o partes de este. | U10: X | Y10: =IF(U10="X","S",IF(V10="X","R","NA")) -> S
A11: 1.5 | B11: Apila materiales según el procedimiento (1.20m de altura y del más grande al más pequeño). | V11: X | Y11: =IF(U11="X","S",IF(V11="X","R","NA")) -> R
A12: 1.6 | B12: Trasladan materiales de manera adecuada según longitud y peso (2 o 3 personas), llevándolas en el mismo hombro. | U12: X | Y12: =IF(U12="X","S",IF(V12="X","R","NA")) -> S
A13: 1.7 | B13: Mantiene el orden y la limpieza en su área de trabajo. | U13: X | Y13: =IF(U13="X","S",IF(V13="X","R","NA")) -> S
A14: 1.8 | B14: Posiciona y asegura la escalera con una inclinación de 4 a 1, sobrepasando el punto de apoyo en mínimo 1m. | U14: X | Y14: =IF(U14="X","S",IF(V14="X","R","NA")) -> S
A15: 1.9 | B15: Respeta la señalización (barreras, cintas de seguridad, área restringida). | U15: X | Y15: =IF(U15="X","S",IF(V15="X","R","NA")) -> S
A16: 1.10 | B16: Utiliza los 3 puntos de apoyo al subir o bajar escaleras. | U16: X | Y16: =IF(U16="X","S",IF(V16="X","R","NA")) -> S
A17: 1.11 | B17: Delimita el área de trabajo con cinta roja o amarilla. | U17: X | Y17: =IF(U17="X","S",IF(V17="X","R","NA")) -> S
A18: 1.12 | B18: Coloca de manera visible la hoja MSDS, en su área de trabajo. | V18: X | Y18: =IF(U18="X","S",IF(V18="X","R","NA")) -> R
A19: 1.13 | B19: Rotula los envases de productos químicos con sus respectivos sticker y rombo NFPA. | W19: X | Y19: =IF(U19="X","S",IF(V19="X","R","NA")) -> NA
A20: 1.14 | B20: Evita usar el celular durante las tareas, en el desplazamiento o durante la conducción. | U20: X | Y20: =IF(U20="X","S",IF(V20="X","R","NA")) -> S
A21: 1.15 | B21: Esta correctamente segregado la interacción entre hombre- máquina y máquina-máquina | U21: X | Y21: =IF(U21="X","S",IF(V21="X","R","NA")) -> S
A22: 2. EQUIPO DE PROTECCION PERSONAL (EPP) | U22: S | V22: R | W22: NA
A23: 2.1 | B23: Utiliza barbiquejo. | U23: X | Y23: =IF(U23="X","S",IF(V23="X","R","NA")) -> S
A24: 2.2 | B24: Utiliza protección de ojos (lentes, careta facial y/o lentes google). | W24: X | Y24: =IF(U24="X","S",IF(V24="X","R","NA")) -> NA
A25: 2.3 | B25: Utiliza lentes claros en recintos cerrados u oscuros. | U25: X | Y25: =IF(U25="X","S",IF(V25="X","R","NA")) -> S
A26: 2.4 | B26: Utiliza protección de manos (guantes de seguridad de acuerdo a la tarea a realizar) | U26: X | Y26: =IF(U26="X","S",IF(V26="X","R","NA")) -> S
A27: 2.5 | B27: Utiliza protección respiratoria adecuada, si la tarea lo requiere (filtros limpios). | V27: X | Y27: =IF(U27="X","S",IF(V27="X","R","NA")) -> R
A28: 2.6 | B28: Utiliza protección auditiva, cuando es necesario. | W28: X | Y28: =IF(U28="X","S",IF(V28="X","R","NA")) -> NA
A29: 2.7 | B29: Utiliza protección total del cuerpo (escarpines, metatarcianos, mandiles de cuero, tyvek, rodillera, etc). | U29: X | Y29: =IF(U29="X","S",IF(V29="X","R","NA")) -> S
A30: 2.8 | B30: Utiliza protector solar | U30: X | Y30: =IF(U30="X","S",IF(V30="X","R","NA")) -> S
A31: 3. HERRAMIENTAS MANUALES Y DE PODER | U31: S | V31: R | W31: NA
A32: 3.1 | B32: Evita el uso de herramientas hechizas. | U32: X | Y32: =IF(U32="X","S",IF(V32="X","R","NA")) -> S
A33: 3.2 | B33: Verifica que las herramientas de poder están bloqueadas (martillo percutor, torna, esmeril, cierra circular, etc), activando hombre muerto. | W33: X | Y33: =IF(U33="X","S",IF(V33="X","R","NA")) -> NA
A34: 3.3 | B34: Utiliza la herramienta adecuada para el trabajo que realiza y de la manera correcta. | W34: X | Y34: =IF(U34="X","S",IF(V34="X","R","NA")) -> NA
A35: 3.4 | B35: Utiliza la herramienta o equipo con la inspección y cinta correspondiente (incluye elementos de izaje). | U35: X | Y35: =IF(U35="X","S",IF(V35="X","R","NA")) -> S
A36: 3.5 | B36: Verifica que los equipos esten con guardas de protección y en buen estado. | U36: X | Y36: =IF(U36="X","S",IF(V36="X","R","NA")) -> S
A37: 4. TRABAJOS CIVILES | U37: S | V37: R | W37: NA
A38: 4.1 | B38: Durante el lanzado de concreto una persona direcciona la manguera de la bomba y usan una cuerda para asegurar una posible salida de aire. | W38: X | Y38: =IF(U38="X","S",IF(V38="X","R","NA")) -> NA
A39: 4.2 | B39: Usa espárragos para el traslado de los paneles metálicos. | W39: X | Y39: =IF(U39="X","S",IF(V39="X","R","NA")) -> NA
A40: 4.3 | B40: Identifica las varillas de acero sobresalientes y coloca los rebar caps (acero verticales) y capuchones (acero horizontales). | W40: X | Y40: =IF(U40="X","S",IF(V40="X","R","NA")) -> NA
...

Sheet BD
A1: Nombre de Observador | B1: Fecha | C1: Actividad/Tarea observada | D1: Area | E1: Disciplina | F1: Empresa | G1: 1. GENERALES | V1: 2. EQUIPO DE PROTECCION PERSONAL (EPP) | AD1: 3. HERRAMIENTAS MANUALES Y DE PODER | AI1: 4. TRABAJOS CIVILES | AM1: ACCIONES CORRECTIVAS
G2: 1.1 | H2: 1.2 | I2: 1.3 | J2: 1.4 | K2: 1.5 | L2: 1.6 | M2: 1.7 | N2: 1.8 | O2: 1.9 | P2: 1.1 | Q2: 1.11 | R2: 1.12 | S2: 1.13 | T2: 1.14 | U2: 1.15 | V2: 2.1 | W2: 2.2 | X2: 2.3 | Y2: 2.4 | Z2: 2.5 | AA2: 2.6 | AB2: 2.7 | AC2: 2.8 | AD2: 3.1 | AE2: 3.2 | AF2: 3.3 | AG2: 3.4 | AH2: 3.5 | AI2: 4.1 | AJ2: 4.2 | AK2: 4.3 | AL2: 4.4 | AM2: MEDIDA CORRECTIVA | AN2: RESPONSABLE | AO2: FECHA
A3: =OPC!F3 -> Edy Villasante | B3: =IF(OPC!R3="","",TEXT(OPC!R3,"mmmm")) -> Mayo | C3: =OPC!F4 -> Instalacion de Malla a tierra | D3: =OPC!C5 -> Chancadora primaria de sulfuros | E3: =OPC!N5 -> Electricidad | F3: =OPC!R4 -> CCICSK | G3: =OPC!Y7 -> S | H3: =OPC!Y8 -> S | I3: =OPC!Y9 -> S | J3: =OPC!Y10 -> S | K3: =OPC!Y11 -> R | L3: =OPC!Y12 -> S | M3: =OPC!Y13 -> S | N3: =OPC!Y14 -> S | O3: =OPC!Y15 -> S | P3: =OPC!Y16 -> S | Q3: =OPC!Y17 -> S | R3: =OPC!Y18 -> R | S3: =OPC!Y19 -> NA | T3: =OPC!Y20 -> S | U3: =OPC!Y21 -> S | V3: =OPC!Y23 -> S | W3: =OPC!Y24 -> NA | X3: =OPC!Y25 -> S | Y3: =OPC!Y26 -> S | Z3: =OPC!Y27 -> R | AA3: =OPC!Y28 -> NA | AB3: =OPC!Y29 -> S | AC3: =OPC!Y30 -> S | AD3: =OPC!Y32 -> S | AE3: =OPC!Y33 -> NA | AF3: =OPC!Y34 -> NA | AG3: =OPC!Y35 -> S | AH3: =OPC!Y36 -> S | AI3: =OPC!Y38 -> NA | AJ3: =OPC!Y39 -> NA | AK3: =OPC!Y40 -> NA | AL3: =OPC!Y41 -> NA | AM3: =OPC!A44 -> Se informo al responsable y se tomo la media correctivas | AN3: =OPC!N44 -> Agustin Matilla | AO3: =IF(OPC!T44="","",TEXT(OPC!T44,"mmmm")) -> Mayo
AM4: =OPC!A45 -> 0 | AN4: =OPC!N45 -> 0 | AO4: =IF(OPC!T45="","",TEXT(OPC!T45,"mmmm"))
AM5: =OPC!A46 -> 0 | AN5: =OPC!N46 -> 0 | AO5: =IF(OPC!T46="","",TEXT(OPC!T46,"mmmm"))
